<?xml version="1.0"?>

<robot name="meine_bot" xmlns:xacro="http://www.ros.org/wiki/xacro">

  <!-- Default Inertial -->
  <xacro:macro name="default_inertial" params="mass">
    <inertial>
      <origin xyz="0 0 0" rpy="0 0 0"/>
      <mass value="${mass}"/>
      <inertia ixx="${inertial}" ixy="0.0" ixz="0.0"
                 iyy="${inertial}" iyz="0.0"
                 izz="${inertial}"
                 />
    </inertial>
  </xacro:macro>

  <xacro:macro name="wheel_default" params="name reflect">
    <link name='wheel_${name}'>

      <xacro:default_inertial mass="${wheel_mass}"/>

      <collision name='wheel_${name}_collision'>
        <origin xyz="0 ${reflect * motor_width} 0" rpy="0 ${reflect * pi/2} ${reflect * pi/2} "/>
        <geometry>
          <cylinder radius="${radius_wheel}" length="${length_wheel}"/>
        </geometry>
      </collision>

      <visual name='wheel_${name}_visual'>
        <origin xyz="0 ${reflect * motor_width} 0" rpy="0 ${reflect * pi/2} ${reflect * pi/2} "/>
        <geometry>
          <cylinder radius="${radius_wheel}" length="${length_wheel}"/>
        </geometry>
        <material name="black">
          <color rgba="0 0 0 1"/>
        </material>
      </visual>

    </link>

    <joint name="wheel_${name}_hinge" type="continuous">
      <origin xyz="0 ${reflect * 0.01} ${z_pos}" rpy="0 0 0" />
      <parent link="motor_${name}"/>
      <child link='wheel_${name}'  />
      <axis xyz="0 1 0" rpy="0 0 0"/>
      <dynamics damping=".01" friction=".01"/>
    </joint>
  </xacro:macro>

  <xacro:macro name="motor_default" params="name reflect">
    <link name='motor_${name}'>

      <xacro:default_inertial mass="2"/>

      <collision name='motor_${name}_collision'>
        <origin xyz="0 0 0" rpy="0 0 0"/>
        <geometry>
          <box size="${motor_length} ${motor_width} ${motor_height}"/>
        </geometry>
      </collision>

      <visual name='motor_${name}_visual'>
        <origin xyz="0 0 0" rpy="0 0 0"/>
        <geometry>
          <box size="${motor_length} ${motor_width} ${motor_height}"/>
        </geometry>
        <material name="yellow">
          <color rgba="1 1 0 1"/>
        </material>
      </visual>

    </link>

    <joint name="motor_${name}_hinge" type="fixed">
      <origin xyz="${-x_pos} ${reflect * y_pos} ${z_pos}" rpy="0 0 0" />
      <parent link="chassis"/>
      <child link='motor_${name}'  />
    </joint>
  </xacro:macro>

</robot>
